Workbook
Name _10_Note_1: '10C'!$D$76
Name _10_Note_1: '10M'!$D$79
Name _10_Note_1: '20C'!$D$77
Name _10_Note_1: ACCT!#REF!
Name _10_Note_2: '10C'!$D$77
Name _10_Note_2: '10M'!$D$80
Name _10_Note_2: '20C'!$D$78
Name _10_Note_2: ACCT!$H$100
Name _10_Note_3: '10C'!$D$78
Name _10_Note_3: '10M'!$D$81
Name _10_Note_3: '20C'!$D$79
Name _10_Note_3: ACCT!$H$101
Name _10_Note_4: '10C'!$D$79
Name _10_Note_4: '10M'!$D$82
Name _10_Note_4: '20C'!$D$80
Name _10_Note_4: ACCT!$H$102
Name _10_Note_5: '10C'!$D$80
Name _10_Note_5: '10M'!$D$83
Name _10_Note_5: '20C'!$D$81
Name _10_Note_5: ACCT!$H$103
Name _20_Note_1: '20B'!$D$131
Name _20_Note_1: '20IC'!$D$134
Name _20_Note_1: '20R'!$D$138
Name _20_Note_1: EMAIL!$F$135
Name _20_Note_1: PHN!$F$134
Name _20_Note_1: POE!$F$135
Name _20_Note_1: PRTY!$G$159
Name _20_Note_1: PRTY!$F$95
Name _20_Note_2: '20B'!$D$132
Name _20_Note_2: '20IC'!$D$135
Name _20_Note_2: '20R'!$D$139
Name _20_Note_2: EMAIL!$F$136
Name _20_Note_2: PHN!$F$135
Name _20_Note_2: POE!$F$136
Name _20_Note_2: PRTY!$G$161
Name _20_Note_2: PRTY!$F$96
Name _20_Note_3: '20B'!$D$133
Name _20_Note_3: '20IC'!$D$136
Name _20_Note_3: '20R'!$D$140
Name _20_Note_3: EMAIL!$F$137
Name _20_Note_3: PHN!$F$136
Name _20_Note_3: POE!$F$137
Name _20_Note_3: PRTY!$G$162
Name _20_Note_3: PRTY!$F$97
Name _20R_Note_1: '20R'!#REF!
Name _30_Note_1: ANOT!$G$15
Name _30_Note_2: ANOT!$G$32
Name _40_Note_1: TRNH!$F$140
Name _40_Note_2: TRNH!$F$141
Name _40_Note_3: TRNH!$F$142
Name _40_Note_4: TRNH!$F$143
Name _40_Note_5: TRNH!$F$144
Name _40_SourceTransactionId: TRNH!$H$7
Name _50_Note_1: '50'!$E$130
Name _50_Note_2: '50'!$E$131
Name _50_Note_3: '50'!$E$132
Name _50_Note_4: '50'!$E$133
Name _60_Note_1: #REF!
Name _60_Note_1: #REF!
Name _60_Note_1: #REF!

Sheet File Specifications
A1: Character Set | B1: ASCII
A2: File Type | B2: Comma Separated Values (CSV) | C2: Note 1
A3: Delimiter | B3: Comma (,)
A4: Field Qualifier | B4: Double Quote (") | C4: Must be used when the field contains the delimiter.
A5: Line Terminator | B5: Carriage Return, Line Feed (CRLF)
A6: Record Id Position | B6: 1 | C6: See Record Ids tab for the list of Record Id values.
A8: Data Type | B8: Format
A9: AMT | B9: -#########.##
A10: CHR | B10: Exclude all control characters
A11: DATE | B11: MM/DD/YYYY
A12: NUMBER | B12: ###########
A13: PHONE | B13: Exactly 10 digits (area code is required)
A14: SSN | B14: Exactly 9 digits
A15: TIME | B15: HH:MM[:SS] (24 hour time) HH:MM[:SS] AM/PM (12 hour time)
A16: ZIP | B16: US or Canadian
A19: Note 1 | B19: Data containing a line break, double-quote, or a comma must be quoted. (If they are not, the file will likely be impossible to process correctly). A double-quote character in a data must be represented by two double-quote characters. See http://en.wikipedia.org/wiki/Comma-separated_values for more information on CSV formatting.

Sheet Record Ids
A1: Record ID | B1: New Rec ID | C1: SaaS timeline | D1: Category | E1: Subcategory | F1: Required? | G1: Instruction | H1: Records Per | J1: Priority
A2: ACCT | B2: ACCT | C2: MVP | D2: Account | E2: Account information | F2: Yes | H2: One | J2: 1
A3: 10C | C3: NA | D3: Account | E3: Custom Account Information
A4: 10M | C4: Data need to be merged with record 10 for MVP | D4: Account | E4: Migrated Account Information | H4: Zero to one
A5: BAL | B5: BAL | C5: MVP | D5: Account | E5: Balance information | F5: Yes | H5: One | J5: 2
A6: 12 | C6: NA | D6: Account | E6: Delinquency information | H6: Zero to one | L6: =ACCT!$G$1 -> 33
A7: 14 | C7: GA | D7: Account | E7: Financial information | H7: Zero to one | L7: =ACCT!$G$1 -> 33
A8: 16 | C8: Later | D8: Account | E8: Alerts | H8: Zero to many per account | L8: =ACCT!$G$1 -> 33
A9: 17 | C9: GA | D9: Loan | E9: Loan Information | F9: No | H9: Zero to one | L9: =ACCT!$G$1 -> 33
A10: 19 | B10: DOC | C10: MVP2 | D10: Doc | E10: Document Information | F10: No | H10: Zero to many
A11: PRTY | B11: PRTY | C11: MVP | D11: Party | E11: Party information | F11: Yes | G11: Must have one and only one primary party (PRIM) | H11: One to many per account | J11: 3
A12: 20B | C12: GA | D12: Party | E12: Party Balances | F12: No | H12: Zero to One per Party | L12: =ACCT!$G$1 -> 33
A13: 20R | C13: GA | D13: Party | E13: Party References | F13: No | H13: Zero to many per Party | L13: =ACCT!$G$1 -> 33
A14: 20C | C14: NA | D14: Party | E14: Custom Party Information | F14: No | H14: Zero to many per Party | L14: =ACCT!$G$1 -> 33
A15: 20IC | C15: Later | D15: Party | E15: Insurance Coverage | H15: Zero to one | L15: =ACCT!$G$1 -> 33
A16: PHN | B16: PHN | C16: MVP | D16: Phone | E16: Phone Information | G16: Use only if UsePhoneTable option is enabled. | H16: Zero to many per Party | J16: 4
A17: POE | B17: POE | C17: MVP | D17: POE | E17: POE Information | G17: Use only if UsePOETable option is enabled. | H17: Zero to many per Party
A18: PADD | B18: PADD | C18: MVP | D18: Previous Address | E18: Previous Address Information | H18: Zero to many per Party
A19: LTRH | B19: LTRH | C19: MVP2 | D19: Letter History | E19: Letter History Information | H19: Zero to many per Party
A20: AKA | B20: AKA | C20: MVP | D20: Party | E20: Aliases | G20: This is not for name changes | H20: Zero to many per Party
A21: 27 | C21: MVP2 | D21: Party | E21: Nearby | H21: Zero to many per Party | I21: This Feature not available in SaaS
A22: 28 | C22: Later | D22: Account or Party | E22: Tasks | G22: These are tasks to be performed after the migration | H22: Zero to many per Account and Party | L22: =ACCT!$G$1 -> 33
A23: 29 | C23: MVP (RM) | D23: Account or Party | E23: Action History | H23: Zero to many per Account and Party | J23: 9 | L23: =ACCT!$G$1 -> 33
A24: ANOT | B24: ANOT | C24: MVP | D24: Account | E24: Notes | G24: Account and relationship notes | H24: Zero to many per Account | I24: Note 1 | J24: 6
A25: PNOT | B25: PNOT | C25: MVP2 | D25: Account | E25: Notes | G25: Account and party notes | H25: Zero to many per Account | J25: Note 2 8
A26: TRNH | B26: TRNH | C26: MVP | D26: Account | E26: Transaction history | G26: Include payments, reversals, and adjustments that have already been applied to the account | H26: Zero to many per Account | J26: 5
A27: 45 | C27: Combine with Transaction History | D27: Account | E27: Memo transactions | G27: Any transaction that must never effect the balance | H27: Zero to many per Account | I27: Future use | L27: =ACCT!$G$1 -> 33
A28: PDTR | B28: PDTR | C28: MVP | D28: Account | E28: Post-dated transactions | G28: Includes payments and adjustments that have not been applied to the account | H28: Zero to many per Account
A29: 50 | C29: GA | D29: Account | E29: Placement history | G29: Include placements, recalls, asset sales, and buy backs | H29: Zero to many per Account | L29: =ACCT!$G$1 -> 33
A30: 51 | C30: GA | D30: Account | E30: Vendor Status Code History | H30: Zero to many per Account | L30: =ACCT!$G$1 -> 33
A31: ACTH | B31: ACTH | C31: MVP | D31: Account | E31: Activity History | H31: Zero to many per Account | J31: 7
A32: PA | B32: PA | C32: MVP | D32: PA Hist | E32: Payment Arrangement | H32: Zero to many per Account
A33: PS | B33: PS | C33: MVP | D33: PA Hist | E33: Payment Schedule | H33: Zero to many per Account
A34: PSC | B34: PSC | C34: MVP2 | D34: PA Hist | E34: Payment Schedule for ECC | H34: Zero to many per Account
A35: PSK | B35: PSK | C35: MVP2 | D35: PA Hist | E35: Payment Schedule for ECK | H35: Zero to many per Account
A36: 61CW | C36: NA | D36: PA Hist | E36: Payment Schedule for CW | H36: Zero to many per Account
A37: 70 | C37: BeyondGA | D37: Account | E37: Collateral information | G37: Cars, houses, etc | H37: Zero to many per Account
A38: 71 | C38: BeyondGA | D38: Account or Collateral | E38: Insurance Information | G38: Insurance on person or collateral | H38: Zero to many per Account or Collateral
A39: 75 | C39: BeyondGA | E39: Detailed Bill Information
A40: 80 | C40: BeyondGA | D40: Account | E40: Debt Buyer purchase history | G40: Required if account was purchased | H40: Zero to many per Account
...

Sheet Change Log
A1: Version | B1: Date | C1: Change Note
B100: 41465 | C100: Removed length from all TIME fields. Time data can be sent in various external formats. See File Specifications tab.
B101: 41465 | C101: Changed the record 40 format. Inserted fields for Vendor Credit and CCC Expense information.
B102: 41466 | C102: Added record 15 (Metro 2 Reporting History)
B103: 41481 | C103: Replaced destination field in record 20 position 30, ARRELENPENDRSPBAL, with ARRELENINIRSPBAL. The old field in that position is calculated from the contents of the new field.
B104: 41491 | C104: Removed table FSDLQSTATUS from the Initial Setup list for accounts. It is still required for the client migration.
B105: 41505 | C105: Added 51 more custom fields to the 99 record for even longer custom records.
B106: 41555 | C106: Added record 16 (Account Alert)
B107: 41556 | C107: Removed record 30 (Account Notes). There will be a separate spreadsheet for migrating account notes.
B108: 41568 | C108: Added record 28 (Account/Party Task)
B109: 41568 | C109: Added record 29 (Action History)
B110: 41570 | C110: Added notes to Converted Account Number (record 10) and Source Party Id (record 20) concerning migrating accounts from multiple systems.
B111: 41571 | C111: Updated Note 1 on record 40
... B135: 43005 | C135: Added Bankruptcy, Deceased, Incarceration, and Litigacy information to end of Record 20
A136: V7 | B136: 43055 | C136: Added letter delete date to record 25
A137: V7 | B137: 43070 | C137: Changed record 20R. Inserted phone flag fields. Removed note about creating a POE record.

Sheet ACCT
A1: Source | G1: =COUNTIF(F5:F77,"MVP")-COUNTIF(G5:G77,"MVP") -> 33 | I1: Destination
A2: FACS | B2: TCS | C2: RM Table | E2: RM Column | F2: SaaS mapping/ timeline | G2: In Migration Import? | I2: Description | J2: Position | K2: Required? | L2: Instructions | M2: Data Type | N2: Length | O2: Oasis table | P2: Oasis Column | Q2: 10 | R2: Min | S2: Max | T2: Foreign Table | U2: Validation
F3: MVP | I3: Rec ID = ACCT | J3: 1 | K3: Yes | Y3: =";ACCT^"&J3&"^"&M3&"^"&N3 -> ;ACCT^1^^
A4: DBACCT | E4: ARACID | F4: MVP | I4: Account_ID | J4: 2 | K4: Yes | Y4: =";ACCT^"&J4&"^"&M4&"^"&N4 -> ;ACCT^2^^
A5: DBACCT | B5: ACCOUNT | C5: =IFERROR(VLOOKUP(E5,'Field Definitions'!$A$1:$S$31597,3),"") -> ARACCOUNT | E5: ARACID | F5: MVP | H5: Core | I5: Account_ID | J5: 3 | L5: Source account number | M5: =IFERROR(VLOOKUP($E5,'Field Definitions'!$A$1:$S$31597,4),"") -> NUMBER | N5: =IFERROR(VLOOKUP($E5,'Field Definitions'!$A$1:$S$31597,5),"") -> 9 | Q5: 1 | R5: =IF(IFERROR(VLOOKUP($E5,'Field Definitions'!$A$1:$S$31597,8),"")=0,"",IFERROR(VLOOKUP($E5,'Field Definitions'!$A$1:$S$31597,8),"")) | S5: =IF(IFERROR(VLOOKUP($E5,'Field Definitions'!$A$1:$S$31597,9),"")=0,"",IFERROR(VLOOKUP($E5,'Field Definitions'!$A$1:$S$31597,9),"")) | T5: =IF(IFERROR(VLOOKUP($E5,'Field Definitions'!$A$1:$S$31597,10),"")=0,"",IFERROR(VLOOKUP($E5,'Field Definitions'!$A$1:$S$31597,10),"")) | U5: =IF(IFERROR(VLOOKUP($E5,'Field Definitions'!$A$1:$S$31597,12),"")=0,"",IFERROR(VLOOKUP($E5,'Field Definitions'!$A$1:$S$31597,12),"")) | Y5: =";ACCT^"&J5&"^"&M5&"^"&N5 -> ;ACCT^3^NUMBER^9
C6: =IFERROR(VLOOKUP(E6,'Field Definitions'!$A$1:$S$31597,3),"") -> ARACCOUNT | E6: ARACCLTID | F6: MVP | I6: =IFERROR(VLOOKUP(E6,'Field Definitions'!$A$1:$S$31597,2),"") -> Client ID | J6: 4 | K6: Yes | L6: ContractID | M6: =IFERROR(VLOOKUP($E6,'Field Definitions'!$A$1:$S$31597,4),"") -> CHR | N6: 255 | Q6: ABC | R6: =IF(IFERROR(VLOOKUP($E6,'Field Definitions'!$A$1:$S$31597,8),"")=0,"",IFERROR(VLOOKUP($E6,'Field Definitions'!$A$1:$S$31597,8),"")) | S6: =IF(IFERROR(VLOOKUP($E6,'Field Definitions'!$A$1:$S$31597,9),"")=0,"",IFERROR(VLOOKUP($E6,'Field Definitions'!$A$1:$S$31597,9),"")) | T6: =IF(IFERROR(VLOOKUP($E6,'Field Definitions'!$A$1:$S$31597,10),"")=0,"",IFERROR(VLOOKUP($E6,'Field Definitions'!$A$1:$S$31597,10),"")) -> ARCLIENT | U6: =IF(IFERROR(VLOOKUP($E6,'Field Definitions'!$A$1:$S$31597,12),"")=0,"",IFERROR(VLOOKUP($E6,'Field Definitions'!$A$1:$S$31597,12),"")) | Y6: =";ACCT^"&J6&"^"&M6&"^"&N6 -> ;ACCT^4^CHR^255
A7: DBCLACCT | B7: ACCOUNT 11 | C7: =IFERROR(VLOOKUP(E7,'Field Definitions'!$A$1:$S$31597,3),"") -> ARACCOUNT | E7: ARACCLACCT | F7: MVP | I7: =IFERROR(VLOOKUP(E7,'Field Definitions'!$A$1:$S$31597,2),"") -> Client Reference Number | J7: 5 | K7: Yes | M7: =IFERROR(VLOOKUP($E7,'Field Definitions'!$A$1:$S$31597,4),"") -> CHR | N7: =IFERROR(VLOOKUP($E7,'Field Definitions'!$A$1:$S$31597,5),"") -> 30 | Q7: 1234111158 | R7: =IF(IFERROR(VLOOKUP($E7,'Field Definitions'!$A$1:$S$31597,8),"")=0,"",IFERROR(VLOOKUP($E7,'Field Definitions'!$A$1:$S$31597,8),"")) | S7: =IF(IFERROR(VLOOKUP($E7,'Field Definitions'!$A$1:$S$31597,9),"")=0,"",IFERROR(VLOOKUP($E7,'Field Definitions'!$A$1:$S$31597,9),"")) | T7: =IF(IFERROR(VLOOKUP($E7,'Field Definitions'!$A$1:$S$31597,10),"")=0,"",IFERROR(VLOOKUP($E7,'Field Definitions'!$A$1:$S$31597,10),"")) | U7: =IF(IFERROR(VLOOKUP($E7,'Field Definitions'!$A$1:$S$31597,12),"")=0,"",IFERROR(VLOOKUP($E7,'Field Definitions'!$A$1:$S$31597,12),"")) | Y7: =";ACCT^"&J7&"^"&M7&"^"&N7 -> ;ACCT^5^CHR^30
C8: =IFERROR(VLOOKUP(E8,'Field Definitions'!$A$1:$S$31597,3),"") -> ARACCOUNT | E8: ARACCLTFWDNAME | F8: NA | I8: =IFERROR(VLOOKUP(E8,'Field Definitions'!$A$1:$S$31597,2),"") -> Forward in client name | L8: Original creditor from forwarding agency | M8: =IFERROR(VLOOKUP($E8,'Field Definitions'!$A$1:$S$31597,4),"") -> CHR | N8: =IFERROR(VLOOKUP($E8,'Field Definitions'!$A$1:$S$31597,5),"") -> 60 | Q8: Ghost Busters Inc | R8: =IF(IFERROR(VLOOKUP($E8,'Field Definitions'!$A$1:$S$31597,8),"")=0,"",IFERROR(VLOOKUP($E8,'Field Definitions'!$A$1:$S$31597,8),"")) | S8: =IF(IFERROR(VLOOKUP($E8,'Field Definitions'!$A$1:$S$31597,9),"")=0,"",IFERROR(VLOOKUP($E8,'Field Definitions'!$A$1:$S$31597,9),"")) | T8: =IF(IFERROR(VLOOKUP($E8,'Field Definitions'!$A$1:$S$31597,10),"")=0,"",IFERROR(VLOOKUP($E8,'Field Definitions'!$A$1:$S$31597,10),"")) | U8: =IF(IFERROR(VLOOKUP($E8,'Field Definitions'!$A$1:$S$31597,12),"")=0,"",IFERROR(VLOOKUP($E8,'Field Definitions'!$A$1:$S$31597,12),"")) | Y8: =";ACCT^"&J8&"^"&M8&"^"&N8 -> ;ACCT^^CHR^60
A9: DBINCDTE | B9: ACCOUNT 12 | C9: =IFERROR(VLOOKUP(E9,'Field Definitions'!$A$1:$S$31597,3),"") -> ARACCOUNT | E9: ARACSRVDTE | F9: MVP | I9: =IFERROR(VLOOKUP(E9,'Field Definitions'!$A$1:$S$31597,2),"") -> Service Date | J9: 6 | M9: =IFERROR(VLOOKUP($E9,'Field Definitions'!$A$1:$S$31597,4),"") -> DATE | N9: =IFERROR(VLOOKUP($E9,'Field Definitions'!$A$1:$S$31597,5),"") -> 10 | Q9: 01/09/2010 | R9: =IF(IFERROR(VLOOKUP($E9,'Field Definitions'!$A$1:$S$31597,8),"")=0,"",IFERROR(VLOOKUP($E9,'Field Definitions'!$A$1:$S$31597,8),"")) | S9: =IF(IFERROR(VLOOKUP($E9,'Field Definitions'!$A$1:$S$31597,9),"")=0,"",IFERROR(VLOOKUP($E9,'Field Definitions'!$A$1:$S$31597,9),"")) | T9: =IF(IFERROR(VLOOKUP($E9,'Field Definitions'!$A$1:$S$31597,10),"")=0,"",IFERROR(VLOOKUP($E9,'Field Definitions'!$A$1:$S$31597,10),"")) | U9: =IF(IFERROR(VLOOKUP($E9,'Field Definitions'!$A$1:$S$31597,12),"")=0,"",IFERROR(VLOOKUP($E9,'Field Definitions'!$A$1:$S$31597,12),"")) | Y9: =";ACCT^"&J9&"^"&M9&"^"&N9 -> ;ACCT^6^DATE^10
A10: DBLSTDTE | B10: ACCOUNT 14 | C10: =IFERROR(VLOOKUP(E10,'Field Definitions'!$A$1:$S$31597,3),"") -> ARACCOUNT | E10: ARACLSTDTE | F10: MVP | I10: =IFERROR(VLOOKUP(E10,'Field Definitions'!$A$1:$S$31597,2),"") -> Listed Date | J10: 7 | K10: Yes | M10: =IFERROR(VLOOKUP($E10,'Field Definitions'!$A$1:$S$31597,4),"") -> DATE | N10: =IFERROR(VLOOKUP($E10,'Field Definitions'!$A$1:$S$31597,5),"") -> 10 | Q10: 01/13/2011 | R10: =IF(IFERROR(VLOOKUP($E10,'Field Definitions'!$A$1:$S$31597,8),"")=0,"",IFERROR(VLOOKUP($E10,'Field Definitions'!$A$1:$S$31597,8),"")) | S10: =IF(IFERROR(VLOOKUP($E10,'Field Definitions'!$A$1:$S$31597,9),"")=0,"",IFERROR(VLOOKUP($E10,'Field Definitions'!$A$1:$S$31597,9),"")) | T10: =IF(IFERROR(VLOOKUP($E10,'Field Definitions'!$A$1:$S$31597,10),"")=0,"",IFERROR(VLOOKUP($E10,'Field Definitions'!$A$1:$S$31597,10),"")) | U10: =IF(IFERROR(VLOOKUP($E10,'Field Definitions'!$A$1:$S$31597,12),"")=0,"",IFERROR(VLOOKUP($E10,'Field Definitions'!$A$1:$S$31597,12),"")) | Y10: =";ACCT^"&J10&"^"&M10&"^"&N10 -> ;ACCT^7^DATE^10
C11: =IFERROR(VLOOKUP(E11,'Field Definitions'!$A$1:$S$31597,3),"") -> ARRELATIONSHIP | E11: ARRELUSERID | F11: Later (assignment) | I11: =IFERROR(VLOOKUP(E11,'Field Definitions'!$A$1:$S$31597,2),"") -> Relationship user | L11: Assigned collector. This data will not be used on non-responsible parties | M11: =IFERROR(VLOOKUP($E11,'Field Definitions'!$A$1:$S$31597,4),"") -> CHR | N11: =IFERROR(VLOOKUP($E11,'Field Definitions'!$A$1:$S$31597,5),"") -> 4 | Q11: OSC | R11: =IF(IFERROR(VLOOKUP($E11,'Field Definitions'!$A$1:$S$31597,8),"")=0,"",IFERROR(VLOOKUP($E11,'Field Definitions'!$A$1:$S$31597,8),"")) | S11: =IF(IFERROR(VLOOKUP($E11,'Field Definitions'!$A$1:$S$31597,9),"")=0,"",IFERROR(VLOOKUP($E11,'Field Definitions'!$A$1:$S$31597,9),"")) | T11: =IF(IFERROR(VLOOKUP($E11,'Field Definitions'!$A$1:$S$31597,10),"")=0,"",IFERROR(VLOOKUP($E11,'Field Definitions'!$A$1:$S$31597,10),"")) -> STUSER | U11: =IF(IFERROR(VLOOKUP($E11,'Field Definitions'!$A$1:$S$31597,12),"")=0,"",IFERROR(VLOOKUP($E11,'Field Definitions'!$A$1:$S$31597,12),"")) | Y11: =";ACCT^"&J11&"^"&M11&"^"&N11 -> ;ACCT^^CHR^4
C12: =IFERROR(VLOOKUP(E12,'Field Definitions'!$A$1:$S$31597,3),"") -> ARACCOUNT | E12: FSACTYPE | F12: NA | I12: =IFERROR(VLOOKUP(E12,'Field Definitions'!$A$1:$S$31597,2),"") -> Account Type | M12: =IFERROR(VLOOKUP($E12,'Field Definitions'!$A$1:$S$31597,4),"") -> CHR | N12: =IFERROR(VLOOKUP($E12,'Field Definitions'!$A$1:$S$31597,5),"") -> 1 | Q12: R | R12: =IF(IFERROR(VLOOKUP($E12,'Field Definitions'!$A$1:$S$31597,8),"")=0,"",IFERROR(VLOOKUP($E12,'Field Definitions'!$A$1:$S$31597,8),"")) | S12: =IF(IFERROR(VLOOKUP($E12,'Field Definitions'!$A$1:$S$31597,9),"")=0,"",IFERROR(VLOOKUP($E12,'Field Definitions'!$A$1:$S$31597,9),"")) | T12: =IF(IFERROR(VLOOKUP($E12,'Field Definitions'!$A$1:$S$31597,10),"")=0,"",IFERROR(VLOOKUP($E12,'Field Definitions'!$A$1:$S$31597,10),"")) | U12: =IF(IFERROR(VLOOKUP($E12,'Field Definitions'!$A$1:$S$31597,12),"")=0,"",IFERROR(VLOOKUP($E12,'Field Definitions'!$A$1:$S$31597,12),"")) -> C|Collections|~R|Recovery| | Y12: =";ACCT^"&J12&"^"&M12&"^"&N12 -> ;ACCT^^CHR^1
C13: =IFERROR(VLOOKUP(E13,'Field Definitions'!$A$1:$S$31597,3),"") -> ARACCOUNT | E13: ARACCSNOTES | F13: NA | I13: =IFERROR(VLOOKUP(E13,'Field Definitions'!$A$1:$S$31597,2),"") -> Client Instructions | M13: =IFERROR(VLOOKUP($E13,'Field Definitions'!$A$1:$S$31597,4),"") -> CHR | N13: =IFERROR(VLOOKUP($E13,'Field Definitions'!$A$1:$S$31597,5),"") -> 60 | Q13: Client Instructions | R13: =IF(IFERROR(VLOOKUP($E13,'Field Definitions'!$A$1:$S$31597,8),"")=0,"",IFERROR(VLOOKUP($E13,'Field Definitions'!$A$1:$S$31597,8),"")) | S13: =IF(IFERROR(VLOOKUP($E13,'Field Definitions'!$A$1:$S$31597,9),"")=0,"",IFERROR(VLOOKUP($E13,'Field Definitions'!$A$1:$S$31597,9),"")) | T13: =IF(IFERROR(VLOOKUP($E13,'Field Definitions'!$A$1:$S$31597,10),"")=0,"",IFERROR(VLOOKUP($E13,'Field Definitions'!$A$1:$S$31597,10),"")) | U13: =IF(IFERROR(VLOOKUP($E13,'Field Definitions'!$A$1:$S$31597,12),"")=0,"",IFERROR(VLOOKUP($E13,'Field Definitions'!$A$1:$S$31597,12),"")) | Y13: =";ACCT^"&J13&"^"&M13&"^"&N13 -> ;ACCT^^CHR^60
C14: =IFERROR(VLOOKUP(E14,'Field Definitions'!$A$1:$S$31597,3),"") -> ARACCOUNT | E14: ARACSPNOTE | F14: NA | I14: NO LONGER USED | M14: =IFERROR(VLOOKUP($E14,'Field Definitions'!$A$1:$S$31597,4),"") -> EDITOR | N14: =IFERROR(VLOOKUP($E14,'Field Definitions'!$A$1:$S$31597,5),"") -> 78 | Q14: Special Note | R14: =IF(IFERROR(VLOOKUP($E14,'Field Definitions'!$A$1:$S$31597,8),"")=0,"",IFERROR(VLOOKUP($E14,'Field Definitions'!$A$1:$S$31597,8),"")) | S14: =IF(IFERROR(VLOOKUP($E14,'Field Definitions'!$A$1:$S$31597,9),"")=0,"",IFERROR(VLOOKUP($E14,'Field Definitions'!$A$1:$S$31597,9),"")) | T14: =IF(IFERROR(VLOOKUP($E14,'Field Definitions'!$A$1:$S$31597,10),"")=0,"",IFERROR(VLOOKUP($E14,'Field Definitions'!$A$1:$S$31597,10),"")) | U14: =IF(IFERROR(VLOOKUP($E14,'Field Definitions'!$A$1:$S$31597,12),"")=0,"",IFERROR(VLOOKUP($E14,'Field Definitions'!$A$1:$S$31597,12),"")) | Y14: =";ACCT^"&J14&"^"&M14&"^"&N14 -> ;ACCT^^EDITOR^78
C15: =IFERROR(VLOOKUP(E15,'Field Definitions'!$A$1:$S$31597,3),"") -> ARRELATIONSHIP | E15: ARRELSTATUSID | F15: NA | H15: Status | I15: =IFERROR(VLOOKUP(E15,'Field Definitions'!$A$1:$S$31597,2),"") -> Status | K15: Yes | M15: =IFERROR(VLOOKUP($E15,'Field Definitions'!$A$1:$S$31597,4),"") -> CHR | N15: =IFERROR(VLOOKUP($E15,'Field Definitions'!$A$1:$S$31597,5),"") -> 20 | Q15: NEWR | R15: =IF(IFERROR(VLOOKUP($E15,'Field Definitions'!$A$1:$S$31597,8),"")=0,"",IFERROR(VLOOKUP($E15,'Field Definitions'!$A$1:$S$31597,8),"")) | S15: =IF(IFERROR(VLOOKUP($E15,'Field Definitions'!$A$1:$S$31597,9),"")=0,"",IFERROR(VLOOKUP($E15,'Field Definitions'!$A$1:$S$31597,9),"")) | T15: =IF(IFERROR(VLOOKUP($E15,'Field Definitions'!$A$1:$S$31597,10),"")=0,"",IFERROR(VLOOKUP($E15,'Field Definitions'!$A$1:$S$31597,10),"")) -> ARSTATUS | U15: =IF(IFERROR(VLOOKUP($E15,'Field Definitions'!$A$1:$S$31597,12),"")=0,"",IFERROR(VLOOKUP($E15,'Field Definitions'!$A$1:$S$31597,12),"")) | Y15: =";ACCT^"&J15&"^"&M15&"^"&N15 -> ;ACCT^^CHR^20
C16: =IFERROR(VLOOKUP(E16,'Field Definitions'!$A$1:$S$31597,3),"") -> ARRELATIONSHIP | E16: ARRELPHSDTE | F16: NA | I16: =IFERROR(VLOOKUP(E16,'Field Definitions'!$A$1:$S$31597,2),"") -> Relationship phase chg date | L16: Status change date | M16: =IFERROR(VLOOKUP($E16,'Field Definitions'!$A$1:$S$31597,4),"") -> DATE | N16: =IFERROR(VLOOKUP($E16,'Field Definitions'!$A$1:$S$31597,5),"") -> 10 | Q16: 01/01/2013 | R16: =IF(IFERROR(VLOOKUP($E16,'Field Definitions'!$A$1:$S$31597,8),"")=0,"",IFERROR(VLOOKUP($E16,'Field Definitions'!$A$1:$S$31597,8),"")) | S16: =IF(IFERROR(VLOOKUP($E16,'Field Definitions'!$A$1:$S$31597,9),"")=0,"",IFERROR(VLOOKUP($E16,'Field Definitions'!$A$1:$S$31597,9),"")) | T16: =IF(IFERROR(VLOOKUP($E16,'Field Definitions'!$A$1:$S$31597,10),"")=0,"",IFERROR(VLOOKUP($E16,'Field Definitions'!$A$1:$S$31597,10),"")) | U16: =IF(IFERROR(VLOOKUP($E16,'Field Definitions'!$A$1:$S$31597,12),"")=0,"",IFERROR(VLOOKUP($E16,'Field Definitions'!$A$1:$S$31597,12),"")) | Y16: =";ACCT^"&J16&"^"&M16&"^"&N16 -> ;ACCT^^DATE^10
C17: =IFERROR(VLOOKUP(E17,'Field Definitions'!$A$1:$S$31597,3),"") -> ARRELATIONSHIP | E17: ARRELWAITDTE | F17: NA | I17: =IFERROR(VLOOKUP(E17,'Field Definitions'!$A$1:$S$31597,2),"") -> Follow-up Date | L17: This data will not be used for non-responsible parties. | M17: =IFERROR(VLOOKUP($E17,'Field Definitions'!$A$1:$S$31597,4),"") -> DATE | N17: =IFERROR(VLOOKUP($E17,'Field Definitions'!$A$1:$S$31597,5),"") -> 10 | Q17: 06/01/2013 | R17: =IF(IFERROR(VLOOKUP($E17,'Field Definitions'!$A$1:$S$31597,8),"")=0,"",IFERROR(VLOOKUP($E17,'Field Definitions'!$A$1:$S$31597,8),"")) | S17: =IF(IFERROR(VLOOKUP($E17,'Field Definitions'!$A$1:$S$31597,9),"")=0,"",IFERROR(VLOOKUP($E17,'Field Definitions'!$A$1:$S$31597,9),"")) | T17: =IF(IFERROR(VLOOKUP($E17,'Field Definitions'!$A$1:$S$31597,10),"")=0,"",IFERROR(VLOOKUP($E17,'Field Definitions'!$A$1:$S$31597,10),"")) | U17: =IF(IFERROR(VLOOKUP($E17,'Field Definitions'!$A$1:$S$31597,12),"")=0,"",IFERROR(VLOOKUP($E17,'Field Definitions'!$A$1:$S$31597,12),"")) | Y17: =";ACCT^"&J17&"^"&M17&"^"&N17 -> ;ACCT^^DATE^10
C18: =IFERROR(VLOOKUP(E18,'Field Definitions'!$A$1:$S$31597,3),"") -> ARACCOUNT | E18: ARACDISPUTE | F18: NA | I18: =IFERROR(VLOOKUP(E18,'Field Definitions'!$A$1:$S$31597,2),"") -> Disputed Status | M18: =IFERROR(VLOOKUP($E18,'Field Definitions'!$A$1:$S$31597,4),"") -> CHR | N18: =IFERROR(VLOOKUP($E18,'Field Definitions'!$A$1:$S$31597,5),"") -> 1 | Q18: R | R18: =IF(IFERROR(VLOOKUP($E18,'Field Definitions'!$A$1:$S$31597,8),"")=0,"",IFERROR(VLOOKUP($E18,'Field Definitions'!$A$1:$S$31597,8),"")) | S18: =IF(IFERROR(VLOOKUP($E18,'Field Definitions'!$A$1:$S$31597,9),"")=0,"",IFERROR(VLOOKUP($E18,'Field Definitions'!$A$1:$S$31597,9),"")) | T18: =IF(IFERROR(VLOOKUP($E18,'Field Definitions'!$A$1:$S$31597,10),"")=0,"",IFERROR(VLOOKUP($E18,'Field Definitions'!$A$1:$S$31597,10),"")) | U18: =IF(IFERROR(VLOOKUP($E18,'Field Definitions'!$A$1:$S$31597,12),"")=0,"",IFERROR(VLOOKUP($E18,'Field Definitions'!$A$1:$S$31597,12),"")) -> Y|Yes|~N|No|~R|Resolved| | Y18: =";ACCT^"&J18&"^"&M18&"^"&N18 -> ;ACCT^^CHR^1
C19: =IFERROR(VLOOKUP(E19,'Field Definitions'!$A$1:$S$31597,3),"") -> ARACCOUNT | E19: ARACLITIGATED | F19: NA | I19: =IFERROR(VLOOKUP(E19,'Field Definitions'!$A$1:$S$31597,2),"") -> Litigation Setting | M19: =IFERROR(VLOOKUP($E19,'Field Definitions'!$A$1:$S$31597,4),"") -> CHR | N19: =IFERROR(VLOOKUP($E19,'Field Definitions'!$A$1:$S$31597,5),"") -> 1 | Q19: N | R19: =IF(IFERROR(VLOOKUP($E19,'Field Definitions'!$A$1:$S$31597,8),"")=0,"",IFERROR(VLOOKUP($E19,'Field Definitions'!$A$1:$S$31597,8),"")) | S19: =IF(IFERROR(VLOOKUP($E19,'Field Definitions'!$A$1:$S$31597,9),"")=0,"",IFERROR(VLOOKUP($E19,'Field Definitions'!$A$1:$S$31597,9),"")) | T19: =IF(IFERROR(VLOOKUP($E19,'Field Definitions'!$A$1:$S$31597,10),"")=0,"",IFERROR(VLOOKUP($E19,'Field Definitions'!$A$1:$S$31597,10),"")) | U19: =IF(IFERROR(VLOOKUP($E19,'Field Definitions'!$A$1:$S$31597,12),"")=0,"",IFERROR(VLOOKUP($E19,'Field Definitions'!$A$1:$S$31597,12),"")) -> L||~N||~B|| | Y19: =";ACCT^"&J19&"^"&M19&"^"&N19 -> ;ACCT^^CHR^1
C20: =IFERROR(VLOOKUP(E20,'Field Definitions'!$A$1:$S$31597,3),"") -> ARACCOUNT | E20: ARACBANKRUPT | F20: NA | I20: =IFERROR(VLOOKUP(E20,'Field Definitions'!$A$1:$S$31597,2),"") -> Is Account Involved in a Bankruptcy | L20: Note 4 | M20: =IFERROR(VLOOKUP($E20,'Field Definitions'!$A$1:$S$31597,4),"") -> CHR | N20: =IFERROR(VLOOKUP($E20,'Field Definitions'!$A$1:$S$31597,5),"") -> 1 | Q20: Y | R20: =IF(IFERROR(VLOOKUP($E20,'Field Definitions'!$A$1:$S$31597,8),"")=0,"",IFERROR(VLOOKUP($E20,'Field Definitions'!$A$1:$S$31597,8),"")) | S20: =IF(IFERROR(VLOOKUP($E20,'Field Definitions'!$A$1:$S$31597,9),"")=0,"",IFERROR(VLOOKUP($E20,'Field Definitions'!$A$1:$S$31597,9),"")) | T20: =IF(IFERROR(VLOOKUP($E20,'Field Definitions'!$A$1:$S$31597,10),"")=0,"",IFERROR(VLOOKUP($E20,'Field Definitions'!$A$1:$S$31597,10),"")) | U20: =IF(IFERROR(VLOOKUP($E20,'Field Definitions'!$A$1:$S$31597,12),"")=0,"",IFERROR(VLOOKUP($E20,'Field Definitions'!$A$1:$S$31597,12),"")) -> Y|Yes|~N|No| | Y20: =";ACCT^"&J20&"^"&M20&"^"&N20 -> ;ACCT^^CHR^1
C21: =IFERROR(VLOOKUP(E21,'Field Definitions'!$A$1:$S$31597,3),"") -> ARACCOUNT | E21: FSACTSCLDTE | F21: NA | I21: =IFERROR(VLOOKUP(E21,'Field Definitions'!$A$1:$S$31597,2),"") -> Claim Date | M21: =IFERROR(VLOOKUP($E21,'Field Definitions'!$A$1:$S$31597,4),"") -> DATE | N21: =IFERROR(VLOOKUP($E21,'Field Definitions'!$A$1:$S$31597,5),"") -> 10 | Q21: 06/02/2011 | R21: =IF(IFERROR(VLOOKUP($E21,'Field Definitions'!$A$1:$S$31597,8),"")=0,"",IFERROR(VLOOKUP($E21,'Field Definitions'!$A$1:$S$31597,8),"")) | S21: =IF(IFERROR(VLOOKUP($E21,'Field Definitions'!$A$1:$S$31597,9),"")=0,"",IFERROR(VLOOKUP($E21,'Field Definitions'!$A$1:$S$31597,9),"")) | T21: =IF(IFERROR(VLOOKUP($E21,'Field Definitions'!$A$1:$S$31597,10),"")=0,"",IFERROR(VLOOKUP($E21,'Field Definitions'!$A$1:$S$31597,10),"")) | U21: =IF(IFERROR(VLOOKUP($E21,'Field Definitions'!$A$1:$S$31597,12),"")=0,"",IFERROR(VLOOKUP($E21,'Field Definitions'!$A$1:$S$31597,12),"")) | Y21: =";ACCT^"&J21&"^"&M21&"^"&N21 -> ;ACCT^^DATE^10
C22: =IFERROR(VLOOKUP(E22,'Field Definitions'!$A$1:$S$31597,3),"") -> ARACCOUNT | E22: ARACVIP | F22: NA | I22: =IFERROR(VLOOKUP(E22,'Field Definitions'!$A$1:$S$31597,2),"") -> VIP | M22: =IFERROR(VLOOKUP($E22,'Field Definitions'!$A$1:$S$31597,4),"") -> CHR | N22: =IFERROR(VLOOKUP($E22,'Field Definitions'!$A$1:$S$31597,5),"") -> 1 | Q22: N | R22: =IF(IFERROR(VLOOKUP($E22,'Field Definitions'!$A$1:$S$31597,8),"")=0,"",IFERROR(VLOOKUP($E22,'Field Definitions'!$A$1:$S$31597,8),"")) | S22: =IF(IFERROR(VLOOKUP($E22,'Field Definitions'!$A$1:$S$31597,9),"")=0,"",IFERROR(VLOOKUP($E22,'Field Definitions'!$A$1:$S$31597,9),"")) | T22: =IF(IFERROR(VLOOKUP($E22,'Field Definitions'!$A$1:$S$31597,10),"")=0,"",IFERROR(VLOOKUP($E22,'Field Definitions'!$A$1:$S$31597,10),"")) | U22: =IF(IFERROR(VLOOKUP($E22,'Field Definitions'!$A$1:$S$31597,12),"")=0,"",IFERROR(VLOOKUP($E22,'Field Definitions'!$A$1:$S$31597,12),"")) -> Y|Yes|~N|No| | Y22: =";ACCT^"&J22&"^"&M22&"^"&N22 -> ;ACCT^^CHR^1
C23: =IFERROR(VLOOKUP(E23,'Field Definitions'!$A$1:$S$31597,3),"") -> ARACCOUNT | E23: FSACEMPLOYEE | F23: NA | I23: =IFERROR(VLOOKUP(E23,'Field Definitions'!$A$1:$S$31597,2),"") -> Employee | M23: =IFERROR(VLOOKUP($E23,'Field Definitions'!$A$1:$S$31597,4),"") -> CHR | N23: =IFERROR(VLOOKUP($E23,'Field Definitions'!$A$1:$S$31597,5),"") -> 1 | Q23: N | R23: =IF(IFERROR(VLOOKUP($E23,'Field Definitions'!$A$1:$S$31597,8),"")=0,"",IFERROR(VLOOKUP($E23,'Field Definitions'!$A$1:$S$31597,8),"")) | S23: =IF(IFERROR(VLOOKUP($E23,'Field Definitions'!$A$1:$S$31597,9),"")=0,"",IFERROR(VLOOKUP($E23,'Field Definitions'!$A$1:$S$31597,9),"")) | T23: =IF(IFERROR(VLOOKUP($E23,'Field Definitions'!$A$1:$S$31597,10),"")=0,"",IFERROR(VLOOKUP($E23,'Field Definitions'!$A$1:$S$31597,10),"")) | U23: =IF(IFERROR(VLOOKUP($E23,'Field Definitions'!$A$1:$S$31597,12),"")=0,"",IFERROR(VLOOKUP($E23,'Field Definitions'!$A$1:$S$31597,12),"")) -> Y|Yes|~N|No| | Y23: =";ACCT^"&J23&"^"&M23&"^"&N23 -> ;ACCT^^CHR^1
C24: =IFERROR(VLOOKUP(E24,'Field Definitions'!$A$1:$S$31597,3),"") -> ARACCOUNT | E24: FSACSKIPTRACE | F24: NA | I24: =IFERROR(VLOOKUP(E24,'Field Definitions'!$A$1:$S$31597,2),"") -> Skiptrace Needed | M24: =IFERROR(VLOOKUP($E24,'Field Definitions'!$A$1:$S$31597,4),"") -> CHR | N24: =IFERROR(VLOOKUP($E24,'Field Definitions'!$A$1:$S$31597,5),"") -> 1 | Q24: N | R24: =IF(IFERROR(VLOOKUP($E24,'Field Definitions'!$A$1:$S$31597,8),"")=0,"",IFERROR(VLOOKUP($E24,'Field Definitions'!$A$1:$S$31597,8),"")) | S24: =IF(IFERROR(VLOOKUP($E24,'Field Definitions'!$A$1:$S$31597,9),"")=0,"",IFERROR(VLOOKUP($E24,'Field Definitions'!$A$1:$S$31597,9),"")) | T24: =IF(IFERROR(VLOOKUP($E24,'Field Definitions'!$A$1:$S$31597,10),"")=0,"",IFERROR(VLOOKUP($E24,'Field Definitions'!$A$1:$S$31597,10),"")) | U24: =IF(IFERROR(VLOOKUP($E24,'Field Definitions'!$A$1:$S$31597,12),"")=0,"",IFERROR(VLOOKUP($E24,'Field Definitions'!$A$1:$S$31597,12),"")) -> Y|Yes|~N|No| | Y24: =";ACCT^"&J24&"^"&M24&"^"&N24 -> ;ACCT^^CHR^1
C25: =IFERROR(VLOOKUP(E25,'Field Definitions'!$A$1:$S$31597,3),"") -> ARACCOUNT | E25: FSACSSCRA | F25: NA | I25: =IFERROR(VLOOKUP(E25,'Field Definitions'!$A$1:$S$31597,2),"") -> Soldiers and Sailors Flag | M25: =IFERROR(VLOOKUP($E25,'Field Definitions'!$A$1:$S$31597,4),"") -> CHR | N25: =IFERROR(VLOOKUP($E25,'Field Definitions'!$A$1:$S$31597,5),"") -> 1 | Q25: N | R25: =IF(IFERROR(VLOOKUP($E25,'Field Definitions'!$A$1:$S$31597,8),"")=0,"",IFERROR(VLOOKUP($E25,'Field Definitions'!$A$1:$S$31597,8),"")) | S25: =IF(IFERROR(VLOOKUP($E25,'Field Definitions'!$A$1:$S$31597,9),"")=0,"",IFERROR(VLOOKUP($E25,'Field Definitions'!$A$1:$S$31597,9),"")) | T25: =IF(IFERROR(VLOOKUP($E25,'Field Definitions'!$A$1:$S$31597,10),"")=0,"",IFERROR(VLOOKUP($E25,'Field Definitions'!$A$1:$S$31597,10),"")) | U25: =IF(IFERROR(VLOOKUP($E25,'Field Definitions'!$A$1:$S$31597,12),"")=0,"",IFERROR(VLOOKUP($E25,'Field Definitions'!$A$1:$S$31597,12),"")) -> Y|Yes|~N|No| | Y25: =";ACCT^"&J25&"^"&M25&"^"&N25 -> ;ACCT^^CHR^1
C26: =IFERROR(VLOOKUP(E26,'Field Definitions'!$A$1:$S$31597,3),"") -> ARACCOUNT | E26: ARACCANCID | F26: MVP | H26: Cancel information | I26: =IFERROR(VLOOKUP(E26,'Field Definitions'!$A$1:$S$31597,2),"") -> Cancel Code | J26: 8 | M26: =IFERROR(VLOOKUP($E26,'Field Definitions'!$A$1:$S$31597,4),"") -> CHR | N26: =IFERROR(VLOOKUP($E26,'Field Definitions'!$A$1:$S$31597,5),"") -> 10 | R26: =IF(IFERROR(VLOOKUP($E26,'Field Definitions'!$A$1:$S$31597,8),"")=0,"",IFERROR(VLOOKUP($E26,'Field Definitions'!$A$1:$S$31597,8),"")) | S26: =IF(IFERROR(VLOOKUP($E26,'Field Definitions'!$A$1:$S$31597,9),"")=0,"",IFERROR(VLOOKUP($E26,'Field Definitions'!$A$1:$S$31597,9),"")) | T26: =IF(IFERROR(VLOOKUP($E26,'Field Definitions'!$A$1:$S$31597,10),"")=0,"",IFERROR(VLOOKUP($E26,'Field Definitions'!$A$1:$S$31597,10),"")) -> ARCANCEL | U26: =IF(IFERROR(VLOOKUP($E26,'Field Definitions'!$A$1:$S$31597,12),"")=0,"",IFERROR(VLOOKUP($E26,'Field Definitions'!$A$1:$S$31597,12),"")) | Y26: =";ACCT^"&J26&"^"&M26&"^"&N26 -> ;ACCT^8^CHR^10
A27: DBCANDTE | C27: =IFERROR(VLOOKUP(E27,'Field Definitions'!$A$1:$S$31597,3),"") -> ARACCOUNT | E27: ARACCANCDTE | F27: MVP | I27: =IFERROR(VLOOKUP(E27,'Field Definitions'!$A$1:$S$31597,2),"") -> Cancel Date | J27: 9 | M27: =IFERROR(VLOOKUP($E27,'Field Definitions'!$A$1:$S$31597,4),"") -> DATE | N27: =IFERROR(VLOOKUP($E27,'Field Definitions'!$A$1:$S$31597,5),"") -> 10 | R27: =IF(IFERROR(VLOOKUP($E27,'Field Definitions'!$A$1:$S$31597,8),"")=0,"",IFERROR(VLOOKUP($E27,'Field Definitions'!$A$1:$S$31597,8),"")) | S27: =IF(IFERROR(VLOOKUP($E27,'Field Definitions'!$A$1:$S$31597,9),"")=0,"",IFERROR(VLOOKUP($E27,'Field Definitions'!$A$1:$S$31597,9),"")) | T27: =IF(IFERROR(VLOOKUP($E27,'Field Definitions'!$A$1:$S$31597,10),"")=0,"",IFERROR(VLOOKUP($E27,'Field Definitions'!$A$1:$S$31597,10),"")) | U27: =IF(IFERROR(VLOOKUP($E27,'Field Definitions'!$A$1:$S$31597,12),"")=0,"",IFERROR(VLOOKUP($E27,'Field Definitions'!$A$1:$S$31597,12),"")) | Y27: =";ACCT^"&J27&"^"&M27&"^"&N27 -> ;ACCT^9^DATE^10
C28: =IFERROR(VLOOKUP(E28,'Field Definitions'!$A$1:$S$31597,3),"") -> ARACCOUNT | E28: ARACCANCBAKAMT | F28: MVP | I28: =IFERROR(VLOOKUP(E28,'Field Definitions'!$A$1:$S$31597,2),"") -> Amount Canceled Back | J28: 10 | M28: =IFERROR(VLOOKUP($E28,'Field Definitions'!$A$1:$S$31597,4),"") -> AMT | N28: =IFERROR(VLOOKUP($E28,'Field Definitions'!$A$1:$S$31597,5),"") -> 16 | R28: =IF(IFERROR(VLOOKUP($E28,'Field Definitions'!$A$1:$S$31597,8),"")=0,"",IFERROR(VLOOKUP($E28,'Field Definitions'!$A$1:$S$31597,8),"")) | S28: =IF(IFERROR(VLOOKUP($E28,'Field Definitions'!$A$1:$S$31597,9),"")=0,"",IFERROR(VLOOKUP($E28,'Field Definitions'!$A$1:$S$31597,9),"")) | T28: =IF(IFERROR(VLOOKUP($E28,'Field Definitions'!$A$1:$S$31597,10),"")=0,"",IFERROR(VLOOKUP($E28,'Field Definitions'!$A$1:$S$31597,10),"")) | U28: =IF(IFERROR(VLOOKUP($E28,'Field Definitions'!$A$1:$S$31597,12),"")=0,"",IFERROR(VLOOKUP($E28,'Field Definitions'!$A$1:$S$31597,12),"")) | Y28: =";ACCT^"&J28&"^"&M28&"^"&N28 -> ;ACCT^10^AMT^16
C29: =IFERROR(VLOOKUP(E29,'Field Definitions'!$A$1:$S$31597,3),"") -> ARACCOUNT | E29: ARACCANCCOL | F29: MVP | I29: =IFERROR(VLOOKUP(E29,'Field Definitions'!$A$1:$S$31597,2),"") -> Canceling user | J29: 11 | M29: =IFERROR(VLOOKUP($E29,'Field Definitions'!$A$1:$S$31597,4),"") -> CHR | N29: =IFERROR(VLOOKUP($E29,'Field Definitions'!$A$1:$S$31597,5),"") -> 4 | R29: =IF(IFERROR(VLOOKUP($E29,'Field Definitions'!$A$1:$S$31597,8),"")=0,"",IFERROR(VLOOKUP($E29,'Field Definitions'!$A$1:$S$31597,8),"")) | S29: =IF(IFERROR(VLOOKUP($E29,'Field Definitions'!$A$1:$S$31597,9),"")=0,"",IFERROR(VLOOKUP($E29,'Field Definitions'!$A$1:$S$31597,9),"")) | T29: =IF(IFERROR(VLOOKUP($E29,'Field Definitions'!$A$1:$S$31597,10),"")=0,"",IFERROR(VLOOKUP($E29,'Field Definitions'!$A$1:$S$31597,10),"")) | U29: =IF(IFERROR(VLOOKUP($E29,'Field Definitions'!$A$1:$S$31597,12),"")=0,"",IFERROR(VLOOKUP($E29,'Field Definitions'!$A$1:$S$31597,12),"")) | Y29: =";ACCT^"&J29&"^"&M29&"^"&N29 -> ;ACCT^11^CHR^4
C30: =IFERROR(VLOOKUP(E30,'Field Definitions'!$A$1:$S$31597,3),"") -> ARACCOUNT | E30: ARACCONTACTS | F30: MVP | H30: Contact information | I30: =IFERROR(VLOOKUP(E30,'Field Definitions'!$A$1:$S$31597,2),"") -> The number of contacts | J30: 12 | M30: =IFERROR(VLOOKUP($E30,'Field Definitions'!$A$1:$S$31597,4),"") -> NUMBER | N30: =IFERROR(VLOOKUP($E30,'Field Definitions'!$A$1:$S$31597,5),"") -> 3 | Q30: 1 | R30: =IF(IFERROR(VLOOKUP($E30,'Field Definitions'!$A$1:$S$31597,8),"")=0,"",IFERROR(VLOOKUP($E30,'Field Definitions'!$A$1:$S$31597,8),"")) | S30: =IF(IFERROR(VLOOKUP($E30,'Field Definitions'!$A$1:$S$31597,9),"")=0,"",IFERROR(VLOOKUP($E30,'Field Definitions'!$A$1:$S$31597,9),"")) | T30: =IF(IFERROR(VLOOKUP($E30,'Field Definitions'!$A$1:$S$31597,10),"")=0,"",IFERROR(VLOOKUP($E30,'Field Definitions'!$A$1:$S$31597,10),"")) | U30: =IF(IFERROR(VLOOKUP($E30,'Field Definitions'!$A$1:$S$31597,12),"")=0,"",IFERROR(VLOOKUP($E30,'Field Definitions'!$A$1:$S$31597,12),"")) | Y30: =";ACCT^"&J30&"^"&M30&"^"&N30 -> ;ACCT^12^NUMBER^3
C31: =IFERROR(VLOOKUP(E31,'Field Definitions'!$A$1:$S$31597,3),"") -> ARACCOUNT | E31: ARACCALLS | F31: MVP | I31: =IFERROR(VLOOKUP(E31,'Field Definitions'!$A$1:$S$31597,2),"") -> Number of phone calls dialed | J31: 13 | M31: =IFERROR(VLOOKUP($E31,'Field Definitions'!$A$1:$S$31597,4),"") -> NUMBER | N31: =IFERROR(VLOOKUP($E31,'Field Definitions'!$A$1:$S$31597,5),"") -> 3 | Q31: 3 | R31: =IF(IFERROR(VLOOKUP($E31,'Field Definitions'!$A$1:$S$31597,8),"")=0,"",IFERROR(VLOOKUP($E31,'Field Definitions'!$A$1:$S$31597,8),"")) | S31: =IF(IFERROR(VLOOKUP($E31,'Field Definitions'!$A$1:$S$31597,9),"")=0,"",IFERROR(VLOOKUP($E31,'Field Definitions'!$A$1:$S$31597,9),"")) | T31: =IF(IFERROR(VLOOKUP($E31,'Field Definitions'!$A$1:$S$31597,10),"")=0,"",IFERROR(VLOOKUP($E31,'Field Definitions'!$A$1:$S$31597,10),"")) | U31: =IF(IFERROR(VLOOKUP($E31,'Field Definitions'!$A$1:$S$31597,12),"")=0,"",IFERROR(VLOOKUP($E31,'Field Definitions'!$A$1:$S$31597,12),"")) | Y31: =";ACCT^"&J31&"^"&M31&"^"&N31 -> ;ACCT^13^NUMBER^3
C32: =IFERROR(VLOOKUP(E32,'Field Definitions'!$A$1:$S$31597,3),"") -> ARACCOUNT | E32: ARACLTRS | F32: MVP | I32: =IFERROR(VLOOKUP(E32,'Field Definitions'!$A$1:$S$31597,2),"") -> Number of letters sent | J32: 14 | M32: =IFERROR(VLOOKUP($E32,'Field Definitions'!$A$1:$S$31597,4),"") -> NUMBER | N32: =IFERROR(VLOOKUP($E32,'Field Definitions'!$A$1:$S$31597,5),"") -> 3 | Q32: 10 | R32: =IF(IFERROR(VLOOKUP($E32,'Field Definitions'!$A$1:$S$31597,8),"")=0,"",IFERROR(VLOOKUP($E32,'Field Definitions'!$A$1:$S$31597,8),"")) | S32: =IF(IFERROR(VLOOKUP($E32,'Field Definitions'!$A$1:$S$31597,9),"")=0,"",IFERROR(VLOOKUP($E32,'Field Definitions'!$A$1:$S$31597,9),"")) | T32: =IF(IFERROR(VLOOKUP($E32,'Field Definitions'!$A$1:$S$31597,10),"")=0,"",IFERROR(VLOOKUP($E32,'Field Definitions'!$A$1:$S$31597,10),"")) | U32: =IF(IFERROR(VLOOKUP($E32,'Field Definitions'!$A$1:$S$31597,12),"")=0,"",IFERROR(VLOOKUP($E32,'Field Definitions'!$A$1:$S$31597,12),"")) | Y32: =";ACCT^"&J32&"^"&M32&"^"&N32 -> ;ACCT^14^NUMBER^3
C33: =IFERROR(VLOOKUP(E33,'Field Definitions'!$A$1:$S$31597,3),"") -> ARACCOUNT | E33: ARACLSTLTR | F33: MVP | I33: =IFERROR(VLOOKUP(E33,'Field Definitions'!$A$1:$S$31597,2),"") -> Last Letter Code | J33: 15 | M33: =IFERROR(VLOOKUP($E33,'Field Definitions'!$A$1:$S$31597,4),"") -> CHR | N33: =IFERROR(VLOOKUP($E33,'Field Definitions'!$A$1:$S$31597,5),"") -> 8 | Q33: LTR | R33: =IF(IFERROR(VLOOKUP($E33,'Field Definitions'!$A$1:$S$31597,8),"")=0,"",IFERROR(VLOOKUP($E33,'Field Definitions'!$A$1:$S$31597,8),"")) | S33: =IF(IFERROR(VLOOKUP($E33,'Field Definitions'!$A$1:$S$31597,9),"")=0,"",IFERROR(VLOOKUP($E33,'Field Definitions'!$A$1:$S$31597,9),"")) | T33: =IF(IFERROR(VLOOKUP($E33,'Field Definitions'!$A$1:$S$31597,10),"")=0,"",IFERROR(VLOOKUP($E33,'Field Definitions'!$A$1:$S$31597,10),"")) -> STLETTER | U33: =IF(IFERROR(VLOOKUP($E33,'Field Definitions'!$A$1:$S$31597,12),"")=0,"",IFERROR(VLOOKUP($E33,'Field Definitions'!$A$1:$S$31597,12),"")) | Y33: =";ACCT^"&J33&"^"&M33&"^"&N33 -> ;ACCT^15^CHR^8
C34: =IFERROR(VLOOKUP(E34,'Field Definitions'!$A$1:$S$31597,3),"") -> ARACCOUNT | E34: ARACLTRDTE | F34: MVP | I34: =IFERROR(VLOOKUP(E34,'Field Definitions'!$A$1:$S$31597,2),"") -> Last Letter Sent Date | J34: 16 | M34: =IFERROR(VLOOKUP($E34,'Field Definitions'!$A$1:$S$31597,4),"") -> DATE | N34: =IFERROR(VLOOKUP($E34,'Field Definitions'!$A$1:$S$31597,5),"") -> 10 | Q34: 01/01/2013 | R34: =IF(IFERROR(VLOOKUP($E34,'Field Definitions'!$A$1:$S$31597,8),"")=0,"",IFERROR(VLOOKUP($E34,'Field Definitions'!$A$1:$S$31597,8),"")) | S34: =IF(IFERROR(VLOOKUP($E34,'Field Definitions'!$A$1:$S$31597,9),"")=0,"",IFERROR(VLOOKUP($E34,'Field Definitions'!$A$1:$S$31597,9),"")) | T34: =IF(IFERROR(VLOOKUP($E34,'Field Definitions'!$A$1:$S$31597,10),"")=0,"",IFERROR(VLOOKUP($E34,'Field Definitions'!$A$1:$S$31597,10),"")) | U34: =IF(IFERROR(VLOOKUP($E34,'Field Definitions'!$A$1:$S$31597,12),"")=0,"",IFERROR(VLOOKUP($E34,'Field Definitions'!$A$1:$S$31597,12),"")) | Y34: =";ACCT^"&J34&"^"&M34&"^"&N34 -> ;ACCT^16^DATE^10
C35: =IFERROR(VLOOKUP(E35,'Field Definitions'!$A$1:$S$31597,3),"") -> ARACCOUNT | E35: ARACRETMAIL | F35: MVP | I35: =IFERROR(VLOOKUP(E35,'Field Definitions'!$A$1:$S$31597,2),"") -> Returned Mail | J35: 17 | M35: =IFERROR(VLOOKUP($E35,'Field Definitions'!$A$1:$S$31597,4),"") -> NUMBER | N35: =IFERROR(VLOOKUP($E35,'Field Definitions'!$A$1:$S$31597,5),"") -> 3 | Q35: 2 | R35: =IF(IFERROR(VLOOKUP($E35,'Field Definitions'!$A$1:$S$31597,8),"")=0,"",IFERROR(VLOOKUP($E35,'Field Definitions'!$A$1:$S$31597,8),"")) | S35: =IF(IFERROR(VLOOKUP($E35,'Field Definitions'!$A$1:$S$31597,9),"")=0,"",IFERROR(VLOOKUP($E35,'Field Definitions'!$A$1:$S$31597,9),"")) -> 999 | T35: =IF(IFERROR(VLOOKUP($E35,'Field Definitions'!$A$1:$S$31597,10),"")=0,"",IFERROR(VLOOKUP($E35,'Field Definitions'!$A$1:$S$31597,10),"")) | U35: =IF(IFERROR(VLOOKUP($E35,'Field Definitions'!$A$1:$S$31597,12),"")=0,"",IFERROR(VLOOKUP($E35,'Field Definitions'!$A$1:$S$31597,12),"")) | Y35: =";ACCT^"&J35&"^"&M35&"^"&N35 -> ;ACCT^17^NUMBER^3
C36: =IFERROR(VLOOKUP(E36,'Field Definitions'!$A$1:$S$31597,3),"") -> A3RELATIONSHIP | E36: A3RELPL95LTR | F36: MVP | I36: Initial PL95 Letter Code | J36: 18 | M36: =IFERROR(VLOOKUP($E36,'Field Definitions'!$A$1:$S$31597,4),"") -> CHR | N36: =IFERROR(VLOOKUP($E36,'Field Definitions'!$A$1:$S$31597,5),"") -> 8 | Q36: PL95 | R36: =IF(IFERROR(VLOOKUP($E36,'Field Definitions'!$A$1:$S$31597,8),"")=0,"",IFERROR(VLOOKUP($E36,'Field Definitions'!$A$1:$S$31597,8),"")) | S36: =IF(IFERROR(VLOOKUP($E36,'Field Definitions'!$A$1:$S$31597,9),"")=0,"",IFERROR(VLOOKUP($E36,'Field Definitions'!$A$1:$S$31597,9),"")) | T36: =IF(IFERROR(VLOOKUP($E36,'Field Definitions'!$A$1:$S$31597,10),"")=0,"",IFERROR(VLOOKUP($E36,'Field Definitions'!$A$1:$S$31597,10),"")) -> STLETTER | U36: =IF(IFERROR(VLOOKUP($E36,'Field Definitions'!$A$1:$S$31597,12),"")=0,"",IFERROR(VLOOKUP($E36,'Field Definitions'!$A$1:$S$31597,12),"")) | Y36: =";ACCT^"&J36&"^"&M36&"^"&N36 -> ;ACCT^18^CHR^8
C37: =IFERROR(VLOOKUP(E37,'Field Definitions'!$A$1:$S$31597,3),"") -> A3RELATIONSHIP | E37: A3RELPL95DTE | F37: MVP | I37: Initial PL95 Letter Date | J37: 19 | M37: =IFERROR(VLOOKUP($E37,'Field Definitions'!$A$1:$S$31597,4),"") -> DATE | N37: =IFERROR(VLOOKUP($E37,'Field Definitions'!$A$1:$S$31597,5),"") -> 10 | Q37: 01/01/2012 | R37: =IF(IFERROR(VLOOKUP($E37,'Field Definitions'!$A$1:$S$31597,8),"")=0,"",IFERROR(VLOOKUP($E37,'Field Definitions'!$A$1:$S$31597,8),"")) | S37: =IF(IFERROR(VLOOKUP($E37,'Field Definitions'!$A$1:$S$31597,9),"")=0,"",IFERROR(VLOOKUP($E37,'Field Definitions'!$A$1:$S$31597,9),"")) | T37: =IF(IFERROR(VLOOKUP($E37,'Field Definitions'!$A$1:$S$31597,10),"")=0,"",IFERROR(VLOOKUP($E37,'Field Definitions'!$A$1:$S$31597,10),"")) | U37: =IF(IFERROR(VLOOKUP($E37,'Field Definitions'!$A$1:$S$31597,12),"")=0,"",IFERROR(VLOOKUP($E37,'Field Definitions'!$A$1:$S$31597,12),"")) | Y37: =";ACCT^"&J37&"^"&M37&"^"&N37 -> ;ACCT^19^DATE^10
C38: =IFERROR(VLOOKUP(E38,'Field Definitions'!$A$1:$S$31597,3),"") -> AFACCOUNT | E38: AFACRATEID | F38: MVP | H38: Payments | I38: =IFERROR(VLOOKUP(E38,'Field Definitions'!$A$1:$S$31597,2),"") -> Rate schedule | J38: 20 | K38: Yes | M38: =IFERROR(VLOOKUP($E38,'Field Definitions'!$A$1:$S$31597,4),"") -> CHR | N38: =IFERROR(VLOOKUP($E38,'Field Definitions'!$A$1:$S$31597,5),"") -> 10 | Q38: 10 | R38: =IF(IFERROR(VLOOKUP($E38,'Field Definitions'!$A$1:$S$31597,8),"")=0,"",IFERROR(VLOOKUP($E38,'Field Definitions'!$A$1:$S$31597,8),"")) | S38: =IF(IFERROR(VLOOKUP($E38,'Field Definitions'!$A$1:$S$31597,9),"")=0,"",IFERROR(VLOOKUP($E38,'Field Definitions'!$A$1:$S$31597,9),"")) | T38: =IF(IFERROR(VLOOKUP($E38,'Field Definitions'!$A$1:$S$31597,10),"")=0,"",IFERROR(VLOOKUP($E38,'Field Definitions'!$A$1:$S$31597,10),"")) -> ARRATE | U38: =IF(IFERROR(VLOOKUP($E38,'Field Definitions'!$A$1:$S$31597,12),"")=0,"",IFERROR(VLOOKUP($E38,'Field Definitions'!$A$1:$S$31597,12),"")) | Y38: =";ACCT^"&J38&"^"&M38&"^"&N38 -> ;ACCT^20^CHR^10
C39: =IFERROR(VLOOKUP(E39,'Field Definitions'!$A$1:$S$31597,3),"") -> AFACCOUNT | E39: AFACCASHNOTE | F39: MVP | I39: =IFERROR(VLOOKUP(E39,'Field Definitions'!$A$1:$S$31597,2),"") -> Cashier's notes | J39: 21 | M39: =IFERROR(VLOOKUP($E39,'Field Definitions'!$A$1:$S$31597,4),"") -> EDITOR | N39: =IFERROR(VLOOKUP($E39,'Field Definitions'!$A$1:$S$31597,5),"") -> 68 | Q39: Cashier's note | R39: =IF(IFERROR(VLOOKUP($E39,'Field Definitions'!$A$1:$S$31597,8),"")=0,"",IFERROR(VLOOKUP($E39,'Field Definitions'!$A$1:$S$31597,8),"")) | S39: =IF(IFERROR(VLOOKUP($E39,'Field Definitions'!$A$1:$S$31597,9),"")=0,"",IFERROR(VLOOKUP($E39,'Field Definitions'!$A$1:$S$31597,9),"")) | T39: =IF(IFERROR(VLOOKUP($E39,'Field Definitions'!$A$1:$S$31597,10),"")=0,"",IFERROR(VLOOKUP($E39,'Field Definitions'!$A$1:$S$31597,10),"")) | U39: =IF(IFERROR(VLOOKUP($E39,'Field Definitions'!$A$1:$S$31597,12),"")=0,"",IFERROR(VLOOKUP($E39,'Field Definitions'!$A$1:$S$31597,12),"")) | Y39: =";ACCT^"&J39&"^"&M39&"^"&N39 -> ;ACCT^21^EDITOR^68
C40: =IFERROR(VLOOKUP(E40,'Field Definitions'!$A$1:$S$31597,3),"") -> AFACCOUNT | E40: AFACHOLDDAYS | F40: MVP | I40: =IFERROR(VLOOKUP(E40,'Field Definitions'!$A$1:$S$31597,2),"") -> Transaction Hold Days | J40: 22 | M40: =IFERROR(VLOOKUP($E40,'Field Definitions'!$A$1:$S$31597,4),"") -> NUMBER | N40: =IFERROR(VLOOKUP($E40,'Field Definitions'!$A$1:$S$31597,5),"") -> 3 | Q40: 7 | R40: =IF(IFERROR(VLOOKUP($E40,'Field Definitions'!$A$1:$S$31597,8),"")=0,"",IFERROR(VLOOKUP($E40,'Field Definitions'!$A$1:$S$31597,8),"")) | S40: =IF(IFERROR(VLOOKUP($E40,'Field Definitions'!$A$1:$S$31597,9),"")=0,"",IFERROR(VLOOKUP($E40,'Field Definitions'!$A$1:$S$31597,9),"")) -> 999 | T40: =IF(IFERROR(VLOOKUP($E40,'Field Definitions'!$A$1:$S$31597,10),"")=0,"",IFERROR(VLOOKUP($E40,'Field Definitions'!$A$1:$S$31597,10),"")) | U40: =IF(IFERROR(VLOOKUP($E40,'Field Definitions'!$A$1:$S$31597,12),"")=0,"",IFERROR(VLOOKUP($E40,'Field Definitions'!$A$1:$S$31597,12),"")) | Y40: =";ACCT^"&J40&"^"&M40&"^"&N40 -> ;ACCT^22^NUMBER^3
...

Sheet BAL
A1: Source | D1: SaaS mapping/ timeline | E1: =COUNTIF(D5:D77,"MVP")-COUNTIF(E5:E77,"MVP") -> 27 | G1: Destination
A2: FACS | B2: TCS | E2: In Account Import? | G2: Table | H2: Column | I2: Description | J2: Position | K2: Required? | L2: Instructions | M2: Data Type | N2: Length | O2: 11 | P2: Min | Q2: Max | R2: Foreign Table | S2: Validation
D3: MVP | I3: Rec ID = BAL | J3: 1 | K3: Yes
D4: MVP | I4: Account_ID | J4: 2 | K4: Yes
D5: MVP | F5: Listed at New Business | H5: PRN_InitialBalance | I5: Principal Initial Balance | J5: 3 | K5: Yes | M5: AMT | N5: 10 | O5: 2234.42
D6: MVP | H6: INT_InitialBalance | I6: Interest Initial Balance | J6: 4 | M6: AMT | N6: 10 | O6: 100.23
D7: MVP | H7: LI3_InitialBalance | I7: List 3 Balance Initial Balance | J7: 5 | M7: AMT | N7: 10 | O7: 7
D8: MVP | H8: LI4_InitialBalance | I8: List 4 Balance Initial Balance | J8: 6 | M8: AMT | N8: 10 | O8: 9
D9: MVP | H9: ATYLS_InitialBalance | I9: Attorney List for NB Initial Balance | J9: 7 | M9: AMT | N9: 10 | O9: 23
D10: MVP | H10: CCLIS_InitialBalance | I10: Court Cost list for NB Initial Balance | J10: 8 | M10: AMT | N10: 10 | O10: 19
D11: MVP | F11: Current Balance | H11: PRN_CurrentBalance | I11: Principal Current Balance | J11: 9 | K11: Yes | M11: AMT | N11: 10 | O11: 1001.32
D12: MVP | H12: INT_CurrentBalance | I12: Interest Current Balance | J12: 10 | M12: AMT | N12: 10 | O12: 142.42
D13: MVP | H13: LI3_CurrentBalance | I13: List 3 Balance Current Balance | J13: 11 | M13: AMT | N13: 10 | O13: 6
D14: MVP | H14: LI4_CurrentBalance | I14: List 4 Balance Current Balance | J14: 12 | M14: AMT | N14: 10 | O14: 8
D15: MVP | H15: ATYLS_CurrentBalance | I15: Attorney List for NB Current Balance | J15: 13 | M15: AMT | N15: 10 | O15: 22
D16: MVP | H16: CCLIS_CurrentBalance | I16: Court Cost list for NB Current Balance | J16: 14 | M16: AMT | N16: 10 | O16: 18
D17: MVP | H17: AIN_CurrentBalance | I17: Agency Interest Current Balance | J17: 15 | M17: AMT | N17: 10 | O17: 10
D18: MVP | H18: PJI_CurrentBalance | I18: Postjudgment Interest Current Balance | J18: 16 | M18: AMT | N18: 10 | O18: 12
D19: MVP | H19: CCAGY_CurrentBalance | I19: Court Costs expensed to agency Current Balance | J19: 17 | M19: AMT | N19: 10 | O19: 14
D20: MVP | H20: CCCLT_CurrentBalance | I20: Court Costs billed to client Current Balance | J20: 18 | M20: AMT | N20: 10 | O20: 16
D21: MVP | H21: ATY_CurrentBalance | I21: Attorney Fees Current Balance | J21: 19 | M21: AMT | N21: 10 | O21: 20
D22: MVP | H22: CKFEE_CurrentBalance | I22: Courtesy check fee Current Balance | J22: 20 | M22: AMT | N22: 10 | O22: 24
D23: MVP | H23: MS1_CurrentBalance | I23: Miscellaneous 1 Current Balance | J23: 21 | M23: AMT | N23: 10 | O23: 26
... D29: MVP | H29: REFRC_CurrentBalance | I29: Refund Recovery Current Balance | J29: 27 | M29: AMT | N29: 10 | O29: 38
D30: NA | F30: User Define Balances | H30: UD1_CurrentBalance | I30: User Defined 1 Current Balance | M30: AMT | N30: 10 | O30: 40
D31: NA | H31: UD1_InitialBalance | I31: User Defined 1 Initial Balance | M31: AMT | N31: 10 | O31: 41
D32: NA | H32: UD2_CurrentBalance | I32: User Defined 2 Current Balance | M32: AMT | N32: 10 | O32: 42
D33: NA | H33: UD2_InitialBalance | I33: User Defined 2 Initial Balance | M33: AMT | N33: 10 | O33: 43
D34: NA | H34: UD3_CurrentBalance | I34: User Defined 3 Current Balance | M34: AMT | N34: 10 | O34: 44
D35: NA | H35: UD3_InitialBalance | I35: User Defined 3 Initial Balance | M35: AMT | N35: 10 | O35: 45
D36: NA | H36: UD4_CurrentBalance | I36: User Defined 4 Current Balance | M36: AMT | N36: 10 | O36: 46
D37: NA | H37: UD4_InitialBalance | I37: User Defined 4 Initial Balance | M37: AMT | N37: 10 | O37: 47
D38: NA | H38: UD5_CurrentBalance | I38: User Defined 5 Current Balance | M38: AMT | N38: 10 | O38: 48
D39: NA | H39: UD5_InitialBalance | I39: User Defined 5 Initial Balance | M39: AMT | N39: 10 | O39: 49
D40: NA | H40: UD6_CurrentBalance | I40: User Defined 6 Current Balance | M40: AMT | N40: 10 | O40: 50
D41: MVP | H41: UD6_InitialBalance | I41: User Defined 6 Initial Balance | J41: 28 | M41: AMT | N41: 10 | O41: 51
D42: MVP | H42: UD7_CurrentBalance | I42: User Defined 7 Current Balance | J42: 29 | M42: AMT | N42: 10 | O42: 52
D43: NA | H43: UD7_InitialBalance | I43: User Defined 7 Initial Balance | M43: AMT | N43: 10 | O43: 53
D44: NA | H44: UD8_CurrentBalance | I44: User Defined 8 Current Balance | M44: AMT | N44: 10 | O44: 54
D45: NA | H45: UD8_InitialBalance | I45: User Defined 8 Initial Balance | M45: AMT | N45: 10 | O45: 55
...

Sheet PRTY
A1: Source | D1: SaaS mapping/ timeline | E1: =COUNTIF(D6:D79,"MVP")-COUNTIF(E6:E79,"MVP") -> 0 | G1: Destination
A2: FACS | B2: TCS | G2: Table | H2: Column | I2: Description | J2: Position | K2: Required? | L2: Instructions | M2: Data Type | N2: Length | O2: 20 | P2: 20 | Q2: 20 | R2: Min | S2: Max | T2: Foreign Table | U2: Validation
D3: MVP | E3: MVP | I3: Rec ID = PRTY | J3: 1 | K3: Yes
A4: DBACCT | D4: MVP | E4: MVP | G4: ARACCOUNT | H4: ARACID | I4: Account_ID | J4: 2 | K4: Yes
A5: DBCLNT_"PSC" | D5: MVP | E5: MVP | I5: Consumer_ID | J5: 3 | K5: Yes | L5: Values: P, SE, S, C, G, PA, PR, D, E, N, A
D6: MVP | E6: MVP | F6: Core | G6: =IFERROR(VLOOKUP(H6,'Field Definitions'!$A$1:$S$31597,3),"") -> ARRELATIONSHIP | H6: ARRELTYPID | I6: =IFERROR(VLOOKUP(H6,'Field Definitions'!$A$1:$S$31597,2),"") -> Relationship type key | J6: 4 | K6: Yes | L6: Should have at least 1 record with Primary. For multiple co-makers use CoMaker_1, CoMaker_2, etc. See values below | M6: =IFERROR(VLOOKUP($H6,'Field Definitions'!$A$1:$S$31597,4),"") -> CHR | N6: =IFERROR(VLOOKUP($H6,'Field Definitions'!$A$1:$S$31597,5),"") -> 10 | O6: PRIM | P6: COMAK_1 | Q6: SPOUSE | R6: =IF(IFERROR(VLOOKUP($H6,'Field Definitions'!$A$1:$S$31597,8),"")=0,"",IFERROR(VLOOKUP($H6,'Field Definitions'!$A$1:$S$31597,8),"")) | S6: =IF(IFERROR(VLOOKUP($H6,'Field Definitions'!$A$1:$S$31597,9),"")=0,"",IFERROR(VLOOKUP($H6,'Field Definitions'!$A$1:$S$31597,9),"")) | T6: =IF(IFERROR(VLOOKUP($H6,'Field Definitions'!$A$1:$S$31597,10),"")=0,"",IFERROR(VLOOKUP($H6,'Field Definitions'!$A$1:$S$31597,10),"")) -> ARRELTYPE | U6: AUTH|Authorized User|~BUSINESS|Business|AR43360~COMAK|Comaker|AR13409~DEPEND|Dependent|AR13410~EXEC|Executor|AR43575~GUAR|Guarantor|AR43574~OWNER|Business Owner|AR43359~PRIM|Primary Responsible Party|AR13411~SPOUSE|Spouse|AR13412~ | X6: =";PRTY^"&J6&"^"&M6&"^"&N6 -> ;PRTY^4^CHR^10
D7: MVP | E7: MVP | G7: =IFERROR(VLOOKUP(H7,'Field Definitions'!$A$1:$S$31597,3),"") -> ARRELATIONSHIP | H7: ARRELRESP | I7: =IFERROR(VLOOKUP(H7,'Field Definitions'!$A$1:$S$31597,2),"") -> Responsible | J7: 5 | K7: Yes | L7: Values: Y, N | M7: =IFERROR(VLOOKUP($H7,'Field Definitions'!$A$1:$S$31597,4),"") -> CHR | N7: =IFERROR(VLOOKUP($H7,'Field Definitions'!$A$1:$S$31597,5),"") -> 1 | O7: Y | P7: Y | Q7: N | R7: =IF(IFERROR(VLOOKUP($H7,'Field Definitions'!$A$1:$S$31597,8),"")=0,"",IFERROR(VLOOKUP($H7,'Field Definitions'!$A$1:$S$31597,8),"")) | S7: =IF(IFERROR(VLOOKUP($H7,'Field Definitions'!$A$1:$S$31597,9),"")=0,"",IFERROR(VLOOKUP($H7,'Field Definitions'!$A$1:$S$31597,9),"")) | T7: =IF(IFERROR(VLOOKUP($H7,'Field Definitions'!$A$1:$S$31597,10),"")=0,"",IFERROR(VLOOKUP($H7,'Field Definitions'!$A$1:$S$31597,10),"")) | U7: =IF(IFERROR(VLOOKUP($H7,'Field Definitions'!$A$1:$S$31597,12),"")=0,"",IFERROR(VLOOKUP($H7,'Field Definitions'!$A$1:$S$31597,12),"")) -> Y|Yes|~N|No| | X7: =";PRTY^"&J7&"^"&M7&"^"&N7 -> ;PRTY^5^CHR^1
D8: MVP | E8: MVP | G8: =IFERROR(VLOOKUP(H8,'Field Definitions'!$A$1:$S$31597,3),"") -> ARENTITY | H8: ARENFNM | I8: =IFERROR(VLOOKUP(H8,'Field Definitions'!$A$1:$S$31597,2),"") -> First Name | J8: 6 | M8: =IFERROR(VLOOKUP($H8,'Field Definitions'!$A$1:$S$31597,4),"") -> CHR | N8: =IFERROR(VLOOKUP($H8,'Field Definitions'!$A$1:$S$31597,5),"") -> 40 | O8: First name | P8: Firstname | Q8: First name | R8: =IF(IFERROR(VLOOKUP($H8,'Field Definitions'!$A$1:$S$31597,8),"")=0,"",IFERROR(VLOOKUP($H8,'Field Definitions'!$A$1:$S$31597,8),"")) | S8: =IF(IFERROR(VLOOKUP($H8,'Field Definitions'!$A$1:$S$31597,9),"")=0,"",IFERROR(VLOOKUP($H8,'Field Definitions'!$A$1:$S$31597,9),"")) | T8: =IF(IFERROR(VLOOKUP($H8,'Field Definitions'!$A$1:$S$31597,10),"")=0,"",IFERROR(VLOOKUP($H8,'Field Definitions'!$A$1:$S$31597,10),"")) | U8: =IF(IFERROR(VLOOKUP($H8,'Field Definitions'!$A$1:$S$31597,12),"")=0,"",IFERROR(VLOOKUP($H8,'Field Definitions'!$A$1:$S$31597,12),"")) | X8: =";PRTY^"&J8&"^"&M8&"^"&N8 -> ;PRTY^6^CHR^40
D9: MVP | E9: MVP | G9: ARENTITY | H9: ARENMNM | I9: Middle Name | J9: 7 | M9: CHR | N9: 45 | P9: Y | X9: =";PRTY^"&J9&"^"&M9&"^"&N9 -> ;PRTY^7^CHR^45
D10: MVP | E10: MVP | G10: =IFERROR(VLOOKUP(H10,'Field Definitions'!$A$1:$S$31597,3),"") -> ARENTITY | H10: ARENLNM | I10: =IFERROR(VLOOKUP(H10,'Field Definitions'!$A$1:$S$31597,2),"") -> Last Name | J10: 8 | K10: Yes | M10: =IFERROR(VLOOKUP($H10,'Field Definitions'!$A$1:$S$31597,4),"") -> CHR | N10: =IFERROR(VLOOKUP($H10,'Field Definitions'!$A$1:$S$31597,5),"") -> 100 | O10: of Primary | P10: ofComak | Q10: of Spouse | R10: =IF(IFERROR(VLOOKUP($H10,'Field Definitions'!$A$1:$S$31597,8),"")=0,"",IFERROR(VLOOKUP($H10,'Field Definitions'!$A$1:$S$31597,8),"")) | S10: =IF(IFERROR(VLOOKUP($H10,'Field Definitions'!$A$1:$S$31597,9),"")=0,"",IFERROR(VLOOKUP($H10,'Field Definitions'!$A$1:$S$31597,9),"")) | T10: =IF(IFERROR(VLOOKUP($H10,'Field Definitions'!$A$1:$S$31597,10),"")=0,"",IFERROR(VLOOKUP($H10,'Field Definitions'!$A$1:$S$31597,10),"")) | U10: =IF(IFERROR(VLOOKUP($H10,'Field Definitions'!$A$1:$S$31597,12),"")=0,"",IFERROR(VLOOKUP($H10,'Field Definitions'!$A$1:$S$31597,12),"")) | X10: =";PRTY^"&J10&"^"&M10&"^"&N10 -> ;PRTY^8^CHR^100
D11: MVP | E11: MVP | G11: =IFERROR(VLOOKUP(H11,'Field Definitions'!$A$1:$S$31597,3),"") -> ARENTITY | H11: ARENADR | I11: =IFERROR(VLOOKUP(H11,'Field Definitions'!$A$1:$S$31597,2),"") -> Address Line | J11: 9 | M11: =IFERROR(VLOOKUP($H11,'Field Definitions'!$A$1:$S$31597,4),"") -> CHR | N11: 150 | O11: 123 Someplace St | P11: 123 Someplace St | Q11: 123 Someplace St | R11: =IF(IFERROR(VLOOKUP($H11,'Field Definitions'!$A$1:$S$31597,8),"")=0,"",IFERROR(VLOOKUP($H11,'Field Definitions'!$A$1:$S$31597,8),"")) | S11: =IF(IFERROR(VLOOKUP($H11,'Field Definitions'!$A$1:$S$31597,9),"")=0,"",IFERROR(VLOOKUP($H11,'Field Definitions'!$A$1:$S$31597,9),"")) | T11: =IF(IFERROR(VLOOKUP($H11,'Field Definitions'!$A$1:$S$31597,10),"")=0,"",IFERROR(VLOOKUP($H11,'Field Definitions'!$A$1:$S$31597,10),"")) | U11: =IF(IFERROR(VLOOKUP($H11,'Field Definitions'!$A$1:$S$31597,12),"")=0,"",IFERROR(VLOOKUP($H11,'Field Definitions'!$A$1:$S$31597,12),"")) | X11: =";PRTY^"&J11&"^"&M11&"^"&N11 -> ;PRTY^9^CHR^150
D12: MVP | E12: MVP | G12: =IFERROR(VLOOKUP(H12,'Field Definitions'!$A$1:$S$31597,3),"") -> ARENTITY | H12: ARENUNT | I12: =IFERROR(VLOOKUP(H12,'Field Definitions'!$A$1:$S$31597,2),"") -> Address Unit (Apt#, POBox #) | J12: 10 | M12: =IFERROR(VLOOKUP($H12,'Field Definitions'!$A$1:$S$31597,4),"") -> CHR | N12: 150 | O12: Apt 123 | P12: ,Apt 123 | Q12: Apt 123 | R12: =IF(IFERROR(VLOOKUP($H12,'Field Definitions'!$A$1:$S$31597,8),"")=0,"",IFERROR(VLOOKUP($H12,'Field Definitions'!$A$1:$S$31597,8),"")) | S12: =IF(IFERROR(VLOOKUP($H12,'Field Definitions'!$A$1:$S$31597,9),"")=0,"",IFERROR(VLOOKUP($H12,'Field Definitions'!$A$1:$S$31597,9),"")) | T12: =IF(IFERROR(VLOOKUP($H12,'Field Definitions'!$A$1:$S$31597,10),"")=0,"",IFERROR(VLOOKUP($H12,'Field Definitions'!$A$1:$S$31597,10),"")) | U12: =IF(IFERROR(VLOOKUP($H12,'Field Definitions'!$A$1:$S$31597,12),"")=0,"",IFERROR(VLOOKUP($H12,'Field Definitions'!$A$1:$S$31597,12),"")) | X12: =";PRTY^"&J12&"^"&M12&"^"&N12 -> ;PRTY^10^CHR^150
D13: MVP | E13: MVP | G13: =IFERROR(VLOOKUP(H13,'Field Definitions'!$A$1:$S$31597,3),"") -> ARENTITY | H13: ARENCTY | I13: =IFERROR(VLOOKUP(H13,'Field Definitions'!$A$1:$S$31597,2),"") -> City | J13: 11 | M13: =IFERROR(VLOOKUP($H13,'Field Definitions'!$A$1:$S$31597,4),"") -> CHR | N13: 50 | O13: Somecity | P13: Somecity | Q13: Somecity | R13: =IF(IFERROR(VLOOKUP($H13,'Field Definitions'!$A$1:$S$31597,8),"")=0,"",IFERROR(VLOOKUP($H13,'Field Definitions'!$A$1:$S$31597,8),"")) | S13: =IF(IFERROR(VLOOKUP($H13,'Field Definitions'!$A$1:$S$31597,9),"")=0,"",IFERROR(VLOOKUP($H13,'Field Definitions'!$A$1:$S$31597,9),"")) | T13: =IF(IFERROR(VLOOKUP($H13,'Field Definitions'!$A$1:$S$31597,10),"")=0,"",IFERROR(VLOOKUP($H13,'Field Definitions'!$A$1:$S$31597,10),"")) | U13: =IF(IFERROR(VLOOKUP($H13,'Field Definitions'!$A$1:$S$31597,12),"")=0,"",IFERROR(VLOOKUP($H13,'Field Definitions'!$A$1:$S$31597,12),"")) | X13: =";PRTY^"&J13&"^"&M13&"^"&N13 -> ;PRTY^11^CHR^50
